Workbook
Name SegmentaçãodeDados_CLIENTE: #REF!
Name SegmentaçãodeDados_PRAZO__DIAS: #REF!

Sheet BASE
A1: CLIENTES | C1: STATUS | E1: VEICULO | G1: ORIGEM
A2: ADM | C2: CONTRATADO | E2: LS GRANELEIRO | G2: ABADIA DE GOIAS-GO
A3: AMAGGI | C3: AGUARDANDO OC | E3: LS SIDER | G3: ABADIA DOS DOURADOS-MG
A4: BOA ESPERANÇA | C4: AGUARDANDO GR | E4: BITREM | G4: ABADIANIA-GO
A5: BRASIL AGRO | C5: CARREGADO | E5: VANDERLEIA | G5: ABAETE-MG
A6: BUNGE | C6: EM TRANSITO | E6: VANDERLEIA SIDER | G6: ABAETETUBA-PA
A7: CARGILL | C7: FALTA CONTRATAR | E7: 4º EIXOS | G7: ABAIARA-CE
A8: CARLOS POLATO | C8: 1ª PERNA | E8: 4º EIXOS SIDER | G8: ABAIRA-BA
A9: CDI / STONEX | C9: FALTA AGENDAR | E9: RODOTREM | G9: ABARE-BA
A10: COFCO | C10: FINALIZADO | E10: RODOTREM SIDER | G10: ABATIA-PR
A11: COOAMI | C11: AGENDADO | E11: TRUCK | G11: ABDON BATISTA-SC
A12: LDC | C12: MANUTENÇÃO | E12: TRUCK SIDER | G12: ABEL FIGUEIREDO-PA
... A14: NUTRADE | C14: AGUARDANDO CARREGAMENTO | E14: BITRUCK SIDER | G14: ABRE CAMPO-MG
C15: LIBERADO | G15: ABREU E LIMA-PE
C16: AGUARDANDO NFE | G16: ABREULANDIA-TO
G17: ACAIACA-MG
G18: ACAILANDIA-MA
G19: ACAJUTIBA-BA
G20: ACARA-PA
G21: ACARAPE-CE
G22: ACARAU-CE
G23: ACARI-RN
G24: ACAUA-PI
G25: ACEGUA-RS
G26: ACOPIARA-CE
G27: ACORIZAL-MT
G28: ACRELANDIA-AC
... G3444: OLHOS-D'AGUA-MG
A3445: OMNICOTTON | G3445: OLIMPIA-SP
A3446: PICCININ | G3446: OLIMPIO NORONHA-MG
A3447: SCHEFFER | G3447: OLINDA-PE
A3448: SCHENKEL | G3448: OLINDA NOVA DO MARANHAO-MA
A3449: SLC | G3449: OLINDINA-BA
G3450: OLIVEDOS-PB
G3451: OLIVEIRA-MG
G3452: OLIVEIRA DE FATIMA-TO
G3453: OLIVEIRA DOS BREJINHOS-BA
G3454: OLIVEIRA FORTES-MG
G3455: OLIVENCA-AL
G3456: ONCA DE PITANGUI-MG
...

Sheet BASE FILIAL
A2: Origem: | B2: ='LIBERAÇÕES'!E2 -> ORIGEM | C2: Coleta: | D2: ='LIBERAÇÕES'!F2 -> COLETA | E2: ='LIBERAÇÕES'!L4 -> -73 | F2: PRAZO FINALIZAR DEAD LINE (DIAS RESTANTES)
A3: Destino: | B3: ='LIBERAÇÕES'!G2 -> DESTINO | C3: Terminal: | D3: ='LIBERAÇÕES'!M2 -> TERMINAL | E3: Tipo de fardo:
A4: Cliente: | B4: ='LIBERAÇÕES'!C2 -> CLIENTE | C4: Volume: | D4: ='LIBERAÇÕES'!I2 -> TOTAL FARDOS | E4: ='LIBERAÇÕES'!N2 -> TIPO DE FARDO
A5: Instrução: | B5: ='LIBERAÇÕES'!J2 -> INSTRUÇÃO | C5: Carregado | D5: =SUM(E8:E17) -> 0 | E5: FRETE EMP.
A6: Dead Line: | B6: ='LIBERAÇÕES'!K2 -> DEAD LINE | C6: Saldo | D6: =D4-D5 -> #VALUE! | E6: ='LIBERAÇÕES'!H2 -> FRETE EMP.
A7: STATUS | B7: PLACA | C7: TIPO VEIC. | D7: FRETE MOT. | E7: QTD. FARDOS

Sheet DASHBOARD

Sheet LIBERAÇÕES
A2: DATA | B2: DATA LIBERAÇÃO | C2: CLIENTE | D2: FILIAL | E2: ORIGEM | F2: COLETA | G2: DESTINO | H2: FRETE EMP. | I2: TOTAL FARDOS | J2: INSTRUÇÃO | K2: DEAD LINE | L2: PRAZO (DIAS) | M2: TERMINAL | N2: TIPO DE FARDO | O2: CARREGADO | P2: A CARREGAR | Q2: OBSERVAÇÃO | S2: FARDOS | T2: =I90 -> 64100 | U2: =1 -> 1
A3: =TODAY() -> 46142 | B3: 46042 | C3: BRASIL AGRO | D3: PRIMAVERA DO LESTE-MT | E3: NOVO SAO JOAQUIM-MT | F3: ALG ITAQUERE | G3: SANTOS-SP | H3: 492 | I3: 1512 | K3: 46062 | L3: =K3-A3 -> -80 | M3: DALASTRA | N3: FARDINHO | O3: =SUM('PRIMAVERA DO LESTE'!E7:E15) -> 1512 | P3: =I3-O3 -> 0 | S3: CARREGADO | T3: =O90 -> #REF! | U3: =O90/I90 -> #REF!
A4: =TODAY() -> 46142 | B4: 46059 | C4: COFCO | D4: LUCAS DO RIO VERDE-MT | E4: LUCAS DO RIO VERDE-MT | F4: ALG S COTTON | G4: SANTOS-SP | H4: 670 | I4: 1206 | J4: S07453-MÃE-JAN-01 | K4: 46069 | L4: =K4-A4 -> -73 | M4: ALAMO | N4: FARDINHO | O4: ='LUCAS DO RIO VERDE'!D4 -> 1206 | P4: =I4-O4 -> 0 | S4: PENDENTE | T4: =P90 -> #REF! | U4: =P90/I90 -> #REF!
A5: =TODAY() -> 46142 | B5: 46059 | C5: COFCO | D5: LUCAS DO RIO VERDE-MT | E5: LUCAS DO RIO VERDE-MT | F5: ALG S COTTON | G5: CUBATAO-SP | H5: 670 | I5: 169 | J5: RODO-M37-JAN26-13 | K5: 46066 | L5: =K5-A5 -> -76 | M5: ISIS | N5: FARDINHO | O5: 169 | P5: =I5-O5 -> 0
A6: =TODAY() -> 46142 | B6: 46059 | C6: COFCO | D6: LUCAS DO RIO VERDE-MT | E6: LUCAS DO RIO VERDE-MT | F6: ALG MARAPÉ | G6: CUBATAO-SP | H6: 670 | I6: 0 | J6: WH-CONLINE-NOV25-16-SLM37 | K6: 46066 | L6: =K6-A6 -> -76 | M6: CONLINE | N6: FARDÃO | O6: ='LUCAS DO RIO VERDE'!D26 -> 0 | P6: =I6-O6 -> 0
A7: =TODAY() -> 46142 | B7: 46059 | C7: COFCO | D7: LUCAS DO RIO VERDE-MT | E7: LUCAS DO RIO VERDE-MT | F7: ALG MARAPÉ | G7: CUBATAO-SP | H7: 670 | I7: 7667 | J7: RODO-M36-JAN26-08 | K7: 46069 | L7: =K7-A7 -> -73 | M7: ISIS | N7: FARDÃO | O7: ='LUCAS DO RIO VERDE'!D35 -> 7667 | P7: =I7-O7 -> 0
A8: =TODAY() -> 46142 | B8: 46059 | C8: COFCO | D8: LUCAS DO RIO VERDE-MT | E8: LUCAS DO RIO VERDE-MT | F8: ALG MARAPÉ | G8: SANTOS-SP | H8: 670 | I8: 3477 | J8: RODO-M37-JAN26-07 | K8: 46069 | L8: =K8-A8 -> -73 | M8: MEDLOG | N8: FARDÃO | O8: ='LUCAS DO RIO VERDE'!D85 -> 3477 | P8: =I8-O8 -> 0
A9: =TODAY() -> 46142 | B9: 46059 | C9: SCHEFFER | D9: SAPEZAL-MT | E9: SAPEZAL-MT | F9: ALG RAFAELA | G9: RONDONOPOLIS-MT | H9: 270 | I9: 110 | J9: S/BR/49 | K9: 46069 | L9: =K9-A9 -> -73 | M9: BRADO | N9: FARDÃO | O9: =SAPEZAL!D4 -> 110 | P9: =I9-O9 -> 0
A10: =TODAY() -> 46142 | B10: 46059 | C10: SCHEFFER | D10: SAPEZAL-MT | E10: SAPEZAL-MT | F10: ALG TRES LAGOAS | G10: RONDONOPOLIS-MT | H10: 270 | I10: 440 | J10: S/BR/49 | K10: 46069 | L10: =K10-A10 -> -73 | M10: BRADO | N10: FARDÃO | O10: =SAPEZAL!D12 -> 440 | P10: =I10-O10 -> 0
A11: =TODAY() -> 46142 | B11: 46059 | C11: COFCO | D11: LUCAS DO RIO VERDE-MT | E11: LUCAS DO RIO VERDE-MT | F11: ALG MARAPÉ | G11: SANTOS-SP | H11: 670 | I11: 156 | J11: S07153-A-JAN-01 | K11: 46069 | L11: =K11-A11 -> -73 | M11: SIGMA | N11: FARDÃO | O11: ='LUCAS DO RIO VERDE'!D114 -> 156 | P11: =I11-O11 -> 0
A12: =TODAY() -> 46142 | B12: 46058 | C12: NUTRADE | D12: SINOP-MT | E12: TABAPORA-MT | F12: ALG INDIO POSSESSO | G12: RONDONOPOLIS-MT | H12: 360 | I12: 1980 | J12: RDN-EXP-RDN-25-AL114 | K12: 46081 | L12: =K12-A12 -> -61 | M12: LDC | N12: FARDÃO | O12: =SINOP!D4 -> 1980 | P12: =I12-O12 -> 0
A13: =TODAY() -> 46142 | B13: 46058 | C13: NUTRADE | D13: LUCAS DO RIO VERDE-MT | E13: LUCAS DO RIO VERDE-MT | F13: ALG SANTO ANTONIO | G13: RONDONOPOLIS-MT | H13: 280 | I13: 145 | J13: RDN-DOM-ANP-25-AL111 | K13: 46081 | L13: =K13-A13 -> -61 | M13: LDC | N13: FARDÃO | O13: ='LUCAS DO RIO VERDE'!D124 -> 145 | P13: =I13-O13 -> 0
A14: =TODAY() -> 46142 | B14: 46045 | C14: NUTRADE | D14: LUCAS DO RIO VERDE-MT | E14: LUCAS DO RIO VERDE-MT | F14: ALG LUCAS COTTON | G14: GUARUJA-SP | H14: 650 | I14: 450 | J14: 25424HK-04A | K14: 46090 | L14: =K14-A14 -> -52 | M14: MOVECITA | N14: FARDINHO | O14: ='LUCAS DO RIO VERDE'!D137 -> 0 | P14: =I14-O14 -> 450 | Q14: LOTE CANCELADO PELO CLIENTE
A15: =TODAY() -> 46142 | B15: 46045 | C15: NUTRADE | D15: SINOP-MT | E15: IPIRANGA DO NORTE-MT | F15: ALG HORIZONTINA | G15: GUARUJA-SP | H15: 650 | I15: 264 | J15: 25424HK-04A | K15: 46090 | L15: =K15-A15 -> -52 | M15: MOVECITA | N15: FARDINHO | O15: =SINOP!D73 -> 775 | P15: =I15-O15 -> -511 | Q15: LOTE CANCELADO PELO CLIENTE
A16: =TODAY() -> 46142 | B16: 46049 | C16: BOA ESPERANÇA | D16: LUCAS DO RIO VERDE-MT | E16: TAPURAH-MT | F16: ALG ELDORADO | G16: GUARUJA-SP | H16: 640 | I16: 200 | J16: BOA02525 | K16: 46071 | L16: =K16-A16 -> -71 | M16: MOVECITA | N16: FARDINHO | O16: ='LUCAS DO RIO VERDE'!D147 -> 200 | P16: =I16-O16 -> 0
A17: =TODAY() -> 46142 | B17: 46049 | C17: BOA ESPERANÇA | D17: SINOP-MT | E17: PORTO DOS GAUCHOS-MT | F17: ALG AGROVERA | G17: GUARUJA-SP | H17: 650 | I17: 137 | J17: BOA02525 | K17: 46071 | L17: =K17-A17 -> -71 | M17: MOVECITA | N17: FARDINHO | O17: =SINOP!D20 -> 137 | P17: =I17-O17 -> 0
A18: =TODAY() -> 46142 | B18: 46049 | C18: BOA ESPERANÇA | D18: LUCAS DO RIO VERDE-MT | E18: LUCAS DO RIO VERDE-MT | F18: ALG RIO VERDE | G18: GUARUJA-SP | H18: 630 | I18: 238 | J18: BOA02525 | K18: 46071 | L18: =K18-A18 -> -71 | M18: MOVECITA | N18: FARDINHO | O18: ='LUCAS DO RIO VERDE'!D157 -> 238 | P18: =I18-O18 -> 0
A19: =TODAY() -> 46142 | B19: 46049 | C19: BOA ESPERANÇA | D19: SINOP-MT | E19: IPIRANGA DO NORTE-MT | F19: ALG IPIRANGA | G19: GUARUJA-SP | H19: 650 | I19: 169 | J19: BOA02525 | K19: 46071 | L19: =K19-A19 -> -71 | M19: MOVECITA | N19: FARDINHO | O19: =SINOP!D29 -> 169 | P19: =I19-O19 -> 0
A20: =TODAY() -> 46142 | B20: 46059 | C20: NUTRADE | D20: SORRISO-MT | E20: SORRISO-MT | F20: ALG COTTON ESPERANÇA | G20: NATAL-RN | H20: 862 | I20: 686 | J20: 250071-04 | K20: 46073 | L20: =K20-A20 -> -69 | M20: VICUNHA | N20: FARDINHO | O20: =SORRISO!D4 -> 686 | P20: =I20-O20 -> 0
A21: =TODAY() -> 46142 | B21: 46059 | C21: NUTRADE | D21: LUCAS DO RIO VERDE-MT | E21: LUCAS DO RIO VERDE-MT | F21: ALG LUCAS COTTON | G21: NATAL-RN | H21: 862 | I21: 300 | J21: 250071-04 | K21: 46073 | L21: =K21-A21 -> -69 | M21: VICUNHA | N21: FARDINHO | O21: 300 | P21: =I21-O21 -> 0
A22: =TODAY() -> 46142 | B22: 46059 | C22: COFCO | D22: SINOP-MT | E22: IPIRANGA DO NORTE-MT | F22: ALG 242 | G22: SANTOS-SP | H22: 660 | I22: 157 | J22: S07423-MAR-01 | K22: 46069 | L22: =K22-A22 -> -73 | M22: SIGMA | N22: FARDINHO | O22: =SINOP!D38 -> 157 | P22: =I22-O22 -> 0
A23: =TODAY() -> 46142 | B23: 46059 | C23: COFCO | D23: LUCAS DO RIO VERDE-MT | E23: LUCAS DO RIO VERDE-MT | F23: LUCAS COTTON | G23: CUBATAO-SP | H23: 670 | I23: 331 | J23: RODO-M37-JAN26-04 | K23: 46069 | L23: =K23-A23 -> -73 | M23: ISIS | N23: FARDINHO | O23: ='LUCAS DO RIO VERDE'!D174 -> 331 | P23: =I23-O23 -> 0
A24: =TODAY() -> 46142 | B24: 46045 | C24: COFCO | D24: PRIMAVERA DO LESTE-MT | E24: PRIMAVERA DO LESTE-MT | F24: ALG NOVA GERAÇÃO | G24: CUBATAO-SP | H24: 530 | I24: 1865 | J24: RODO-M37-JAN26-11 | K24: 46073 | L24: =K24-A24 -> -69 | M24: ISIS | N24: FARDINHO | O24: ='PRIMAVERA DO LESTE'!D20 -> 1865 | P24: =I24-O24 -> 0
A25: =TODAY() -> 46142 | B25: 09/0/2026 | C25: COFCO | D25: RONDONOPOLIS-MT | E25: RONDONOPOLIS-MT | F25: ALG TBM LOG | G25: HORIZONTE-CE | H25: 990 | I25: 128 | J25: WH_STN_CONSIG-FEV-01-SANTANA | K25: 46071 | L25: =K25-A25 -> -71 | M25: SANTANA | N25: FARDÃO | O25: =RONDONOPOLIS!D4 -> 128 | P25: =I25-O25 -> 0
A26: =TODAY() -> 46142 | B26: 46064 | C26: COFCO | D26: RONDONOPOLIS-MT | E26: RONDONOPOLIS-MT | F26: ALG TBM LOG | G26: SANTOS-SP | H26: 585 | I26: 0 | J26: WH-S07405-JAN-01 | K26: 46071 | L26: =K26-A26 -> -71 | M26: CONLINE | N26: FARDÃO | O26: =RONDONOPOLIS!D16 -> 0 | P26: =I26-O26 -> 0
A27: =TODAY() -> 46142 | B27: 46064 | C27: COFCO | D27: RONDONOPOLIS-MT | E27: RONDONOPOLIS-MT | F27: ALG TBM LOG | G27: GUARUJA-SP | H27: 585 | I27: 0 | J27: S07389-JAN-01 | K27: 46071 | L27: =K27-A27 -> -71 | M27: CORTES | N27: FARDÃO | O27: =RONDONOPOLIS!D33 -> 0 | P27: =I27-O27 -> 0
A28: =TODAY() -> 46142 | B28: 46064 | C28: COFCO | D28: RONDONOPOLIS-MT | E28: RONDONOPOLIS-MT | F28: ALG TBM LOG | G28: CUBATAO-SP | H28: 585 | I28: 2168 | J28: S07475-MÃE-FEV-02 | K28: 46071 | L28: =K28-A28 -> -71 | M28: ISIS | N28: FARDÃO | O28: =RONDONOPOLIS!D50 -> 2168 | P28: =I28-O28 -> 0
A29: =TODAY() -> 46142 | B29: 46064 | C29: BRASIL AGRO | D29: PRIMAVERA DO LESTE-MT | E29: NOVO SAO JOAQUIM-MT | F29: ALG ITAQUERE | G29: GUARUJA-SP | H29: 570 | I29: 718 | J29: AF237/2025 | K29: 46077 | L29: =K29-A29 -> -65 | M29: CORTES | N29: FARDINHO | O29: ='PRIMAVERA DO LESTE'!D39 -> 718 | P29: =I29-O29 -> 0
A30: =TODAY() -> 46142 | B30: 46067 | C30: COFCO | D30: SAPEZAL-MT | E30: SAPEZAL-MT | F30: ALG BC COTTON | G30: SANTOS-SP | H30: 727 | I30: 863 | J30: RODO-M37-JAN26-06-B | K30: 46081 | L30: =K30-A30 -> -61 | N30: FARDINHO | O30: =SAPEZAL!D21 -> 863 | P30: =I30-O30 -> 0
A31: =TODAY() -> 46142 | B31: 46076 | C31: LDC | D31: SAPEZAL-MT | E31: SAPEZAL-MT | F31: ALG RAFAELA | G31: SANTOS-SP | H31: 660 | I31: 220 | J31: RDN-EXP-SMGS-25-T531 | K31: 46084 | L31: =K31-A31 -> -58 | M31: SMAGALHÃES | N31: FARDÃO | O31: =SAPEZAL!D34 -> 220 | P31: =I31-O31 -> 0
A32: =TODAY() -> 46142 | B32: 46076 | C32: LDC | D32: SAPEZAL-MT | E32: SAPEZAL-MT | F32: ALG RAFAELA | G32: SANTOS-SP | H32: 660 | I32: 880 | J32: RDN-EXP-SMGS-25-T517 | K32: 46084 | L32: =K32-A32 -> -58 | M32: SMAGALHÃES | N32: FARDÃO | O32: =SAPEZAL!D42 -> 880 | P32: =I32-O32 -> 0
A33: =TODAY() -> 46142 | B33: 46081 | C33: COFCO | D33: RONDONOPOLIS-MT | E33: CAMPO VERDE-MT | F33: ALG PRINCESA | G33: SANTOS-SP | H33: 636 | I33: 126 | J33: RODO-M37-JAN26-08 | K33: 46087 | L33: =K33-A33 -> -55 | N33: FARDÃO | O33: =RONDONOPOLIS!D77 -> 126 | P33: =I33-O33 -> 0
A34: =TODAY() -> 46142 | B34: 46081 | C34: COFCO | D34: RONDONOPOLIS-MT | E34: CAMPO VERDE-MT | F34: ALG COOPERPLUMA UBA I | G34: SANTOS-SP | H34: 540 | I34: 175 | J34: S07508-FEV-01 | K34: 46087 | L34: =K34-A34 -> -55 | M34: SIGMA | N34: FARDÃO | O34: 175 | P34: =I34-O34 -> 0
A35: =TODAY() -> 46142 | B35: 46081 | C35: BRASIL AGRO | D35: PRIMAVERA DO LESTE-MT | E35: NOVO SAO JOAQUIM-MT | F35: ALG ITAQUERE | G35: SANTOS-SP | H35: 600 | I35: 481 | K35: 46085 | L35: =K35-A35 -> -57 | M35: DALASTRA | N35: FARDINHO | O35: ='PRIMAVERA DO LESTE'!D51 -> 481 | P35: =I35-O35 -> 0
A36: =TODAY() -> 46142 | B36: 46083 | C36: COFCO | D36: RONDONOPOLIS-MT | E36: CAMPO VERDE-MT | F36: ALG COOPERBEM | G36: CUBATAO-SP | H36: 648 | I36: 1929 | J36: S07414-C-MAR-MÃE-01 | K36: 46087 | L36: =K36-A36 -> -55 | M36: ISIS | N36: FARDÃO | O36: =RONDONOPOLIS!D101 -> 1929 | P36: =I36-O36 -> 0
A37: =TODAY() -> 46142 | B37: 46083 | C37: COFCO | D37: RONDONOPOLIS-MT | E37: CAMPO VERDE-MT | F37: ALG COOPERBEM | G37: CUBATAO-SP | H37: 648 | I37: 150 | J37: WH-S07528-A-MÃE-FEV-01 | K37: 46087 | L37: =K37-A37 -> -55 | M37: CONLINE | N37: FARDÃO | O37: =RONDONOPOLIS!D122 -> 150 | P37: =I37-O37 -> 0
A38: =TODAY() -> 46142 | B38: 46083 | C38: COFCO | D38: RONDONOPOLIS-MT | E38: CAMPO VERDE-MT | F38: ALG COOPERBEM | G38: CUBATAO-SP | H38: 648 | I38: 73 | J38: S07469-MÃE-JAN-01 | K38: 46087 | L38: =K38-A38 -> -55 | M38: ISIS | N38: FARDÃO | O38: =RONDONOPOLIS!D132 -> 73 | P38: =I38-O38 -> 0
A39: =TODAY() -> 46142 | B39: 46083 | C39: COFCO | D39: PRIMAVERA DO LESTE-MT | E39: PRIMAVERA DO LESTE-MT | F39: ALG NOVA GERAÇÃO | G39: CUBATAO-SP | H39: 682 | I39: 4557 | J39: S07499-MÃE-JAN-01 | K39: 46087 | L39: =K39-A39 -> -55 | M39: ISIS | N39: FARDINHO | O39: ='PRIMAVERA DO LESTE'!D61 -> 4557 | P39: =I39-O39 -> 0
A40: =TODAY() -> 46142 | B40: 46083 | C40: COFCO | D40: RONDONOPOLIS-MT | E40: RONDONOPOLIS-MT | F40: ALG TBM LOG | G40: SANTOS-SP | H40: 659 | I40: 3180 | J40: S07466-MÃE-FEV-01 | K40: 46090 | L40: =K40-A40 -> -52 | M40: ALAMO | N40: FARDÃO | O40: 3180 | P40: =I40-O40 -> 0
A41: =TODAY() -> 46142 | B41: 46083 | C41: COFCO | D41: RONDONOPOLIS-MT | E41: RONDONOPOLIS-MT | F41: ALG TBM LOG | G41: CUBATAO-SP | H41: 659 | I41: 319 | J41: WH-RD-S07414-M37-FEV-02 | K41: 46087 | L41: =K41-A41 -> -55 | M41: CONLINE | N41: FARDÃO | O41: 319 | P41: =I41-O41 -> 0
...

Sheet ACESSO - TERMINAIS
A1: TERMINAL | B1: DADOS AGENDAMENTO | C1: LOGIN | D1: SENHA
A2: NG REDEX | B2: VIA EMAIL agendamento@granport.com.br, ana.santos@granport.com.br, rogerio.guedes@granport.com.br Preencher planilha, anexar romaneio, ticket, nf, xml, cte e ficha motorista.
A3: SERRA TERMINAIS | B3: LINK: http://redex.serraterminais.com.br:8888/agendamento/ | C3: 019.361.981-42 | D3: 68388
A4: GELOG (PAULISTA TERMINAIS) | B4: LINK: https://www.microled.app.br/gelog/agendamento/Login.aspx | C4: 38948791000159 | D4: gelog2024
A5: ISIS TERMINAIS | B5: LINK: http://agendamento.isisredex.com.br/Patio1/ | C5: 017.774.112-03 | D5: 755671
A6: DINAMO | B6: LINK: http://redex.grupodinamo.com.br:8980/agendamentoredex2/ | C6: 061.988.851-27 | D6: 864784
A7: TSL | B7: LINK: http://redex.tslredex.com.br/AgendamentoRedex/ | C7: 044.508.931-82 | D7: 861635
A8: DALASTRA | B8: LINK: http://www.dalastra.com.br/agendamentoredex | C8: 017.774.112-03 | D8: 383233
A9: CORTÊS | B9: LINK: http://agendamento.cortes.com.br/Default.aspx CNPJ: 38948791000159 | C9: FIBRAFORTE | D9: UXBPBKXP
A10: TMDL | B10: LINK: https://agendamento.tmdl.com.br/Login.aspx | C10: 38948791000159 | D10: fibraforte
A11: DEPOTCE (CESARI) | B11: LINK: https://app.depotce.com.br/agendamentoAG/ | C11: 017.774.112-03 | D11: 528363
A12: DEPOTCE (CESARI) VIA PORTAL SILO | B12: LINK: https://silo.magnalogistics.com.br/transportador/dashboard/ | C12: fibraforte | D12: Senha123!
A13: MOVECTA (LOCAL FRIO) | B13: CLIENTE MANDA O LINK DE SOLICITAÇÃO JUNTO COM A LIBERAÇÃO DO FRETE, A SOLICITAÇÃO É PREENCHIDA, E O TERMINAL RETORNA DEPOIS COM O AGENDAMENTO SE O CLIENTE NÃO MANDAR, SOLICITAMOS VIA EMAIL. priscila.almoinha@magnalogistics.com.br, atendimento@magnalogistics.com.br ANEXAR PLANILHA E DOCUMENTOS
A14: UNITRADING LOGISTICA | B14: LINK: https://wmsweb.rasio.com.br/agendamento | C14: FIBRA FORTE | D14: FGGJATCG
A15: DELLA VOLPE | B15: VIA EMAIL: grp.santosimportacao@dellavolpe.com.br, wellington.novo@dellavolpe.com.br, vinicius.blanco@dellavolpe.com.br, bruna.lisboa@dellavolpe.com.br, lucas.viana@dellavolpe.com.br Mandar com planilha preenchida, e documentos em anexo.
A16: BCS CUBATÃO | B16: VIA EMAIL: expedicao3.terminal@bcsagf.com.br, expedicao8.terminal@bcsagf.com.br, terminal.cbt@bcsagf.com.br, expedicao5.terminal@bcsagf.com.br Mandar com planilha preenchida, e documentos em anexo.
A17: MOVECTA | B17: LINK: https://silo.magnalogistics.com.br/transportador/login/ | C17: fibraforte | D17: Senha123!
A18: ALAMO | B18: AGENDAMENTO POR EMAIL operacionalsantos@carconbr.com.br; agendamento@alamo.com.br; operacional@jbconex.com.br
A19: SIGMA | B19: LINK: http://54.232.113.39/AgendamentoRedex/ | C19: 019.361.981-42 | D19: 827245
A20: CONLONE | B20: LINK: http://agendamento.conlinessz.com.br | C20: 140.194.249-00 | D20: 328847
A21: ME DLOG | B21: https://medlogdepotweb.mscbr.com.br/SAEWeb/CadMotorista | C21: comercial@fibraforte.agr.br | D21: lh@x0f

Sheet SINOP
A1: Origem: | B1: ='LIBERAÇÕES'!E12 -> TABAPORA-MT | C1: Coleta: | D1: ='LIBERAÇÕES'!F12 -> ALG INDIO POSSESSO | E1: ='LIBERAÇÕES'!L12 -> -61 | F1: PRAZO FINALIZAR DEAD LINE (DIAS RESTANTES)
A2: Destino: | B2: ='LIBERAÇÕES'!G12 -> RONDONOPOLIS-MT | C2: Terminal: | D2: ='LIBERAÇÕES'!M12 -> LDC | E2: Tipo de fardo:
A3: Cliente: | B3: ='LIBERAÇÕES'!C12 -> NUTRADE | C3: Volume: | D3: 1980 | E3: ='LIBERAÇÕES'!N12 -> FARDÃO
A4: Instrução: | B4: ='LIBERAÇÕES'!J12 -> RDN-EXP-RDN-25-AL114 | C4: Carregado | D4: =SUM(E7:E15) -> 1980 | E4: FRETE EMP.
A5: Dead Line: | B5: ='LIBERAÇÕES'!K12 -> 46081 | C5: Saldo | D5: =D3-D4 -> 0 | E5: ='LIBERAÇÕES'!H12 -> 360
A6: STATUS | B6: PLACA | C6: TIPO VEIC. | D6: FRETE MOT. | E6: QTD. FARDOS
A7: FINALIZADO | B7: QCC0H80 | C7: RODOTREM | D7: 310 | E7: 220
A8: FINALIZADO | B8: QCS8G54 | C8: RODOTREM | D8: 310 | E8: 220
A9: FINALIZADO | B9: QBV9F31 | C9: RODOTREM | D9: 300 | E9: 220
A10: FINALIZADO | B10: QCL1H44 | C10: RODOTREM | D10: 300 | E10: 220
A11: FINALIZADO | B11: QCS8G54 | C11: RODOTREM | D11: 300 | E11: 220
A12: FINALIZADO | B12: QCL1H44 | C12: RODOTREM | D12: 300 | E12: 220
A13: FINALIZADO | B13: QCY6F72 | C13: RODOTREM | D13: 300 | E13: 228
A14: FINALIZADO | B14: PGL9872 | C14: RODOTREM | D14: 280 | E14: 212
A15: FINALIZADO | B15: AXB4E11 | C15: RODOTREM | D15: 280 | E15: 220
A17: Origem: | B17: ='LIBERAÇÕES'!E17 -> PORTO DOS GAUCHOS-MT | C17: Coleta: | D17: ='LIBERAÇÕES'!F17 -> ALG AGROVERA | E17: ='LIBERAÇÕES'!L17 -> -71 | F17: PRAZO FINALIZAR DEAD LINE (DIAS RESTANTES)
A18: Destino: | B18: ='LIBERAÇÕES'!G17 -> GUARUJA-SP | C18: Terminal: | D18: ='LIBERAÇÕES'!M17 -> MOVECITA | E18: Tipo de fardo:
A19: Cliente: | B19: ='LIBERAÇÕES'!C17 -> BOA ESPERANÇA | C19: Volume: | D19: ='LIBERAÇÕES'!I17 -> 137 | E19: ='LIBERAÇÕES'!N17 -> FARDINHO
A20: Instrução: | B20: ='LIBERAÇÕES'!J17 -> BOA02525 | C20: Carregado | D20: =SUM(E23:E24) -> 137 | E20: FRETE EMP.
A21: Dead Line: | B21: ='LIBERAÇÕES'!K17 -> 46071 | C21: Saldo | D21: =D19-D20 -> 0 | E21: ='LIBERAÇÕES'!H17 -> 650
A22: STATUS | B22: PLACA | C22: TIPO VEIC. | D22: FRETE MOT. | E22: QTD. FARDOS
A23: FINALIZADO | B23: SQD6D28 | C23: LS SIDER | E23: 137
A26: Origem: | B26: ='LIBERAÇÕES'!E19 -> IPIRANGA DO NORTE-MT | C26: Coleta: | D26: ='LIBERAÇÕES'!F19 -> ALG IPIRANGA | E26: ='LIBERAÇÕES'!L19 -> -71 | F26: PRAZO FINALIZAR DEAD LINE (DIAS RESTANTES)
A27: Destino: | B27: ='LIBERAÇÕES'!G19 -> GUARUJA-SP | C27: Terminal: | D27: ='LIBERAÇÕES'!M19 -> MOVECITA | E27: Tipo de fardo:
A28: Cliente: | B28: ='LIBERAÇÕES'!C19 -> BOA ESPERANÇA | C28: Volume: | D28: ='LIBERAÇÕES'!I19 -> 169 | E28: ='LIBERAÇÕES'!N19 -> FARDINHO
A29: Instrução: | B29: ='LIBERAÇÕES'!J19 -> BOA02525 | C29: Carregado | D29: =SUM(E32:E33) -> 169 | E29: FRETE EMP.
A30: Dead Line: | B30: ='LIBERAÇÕES'!K19 -> 46071 | C30: Saldo | D30: =D28-D29 -> 0 | E30: ='LIBERAÇÕES'!H19 -> 650
A31: STATUS | B31: PLACA | C31: TIPO VEIC. | D31: FRETE MOT. | E31: QTD. FARDOS
A32: FINALIZADO | B32: RAY7E40 | C32: RODOTREM | E32: 169
A35: Origem: | B35: ='LIBERAÇÕES'!E22 -> IPIRANGA DO NORTE-MT | C35: Coleta: | D35: ='LIBERAÇÕES'!F22 -> ALG 242 | E35: ='LIBERAÇÕES'!L22 -> -73 | F35: PRAZO FINALIZAR DEAD LINE (DIAS RESTANTES)
A36: Destino: | B36: ='LIBERAÇÕES'!G22 -> SANTOS-SP | C36: Terminal: | D36: ='LIBERAÇÕES'!M22 -> SIGMA | E36: Tipo de fardo:
A37: Cliente: | B37: ='LIBERAÇÕES'!C22 -> COFCO | C37: Volume: | D37: ='LIBERAÇÕES'!I22 -> 157 | E37: ='LIBERAÇÕES'!N22 -> FARDINHO
A38: Instrução: | B38: ='LIBERAÇÕES'!J22 -> S07423-MAR-01 | C38: Carregado | D38: =SUM(E41:E42) -> 157 | E38: FRETE EMP.
A39: Dead Line: | B39: ='LIBERAÇÕES'!K22 -> 46069 | C39: Saldo | D39: =D37-D38 -> 0 | E39: ='LIBERAÇÕES'!H22 -> 660
A40: STATUS | B40: PLACA | C40: TIPO VEIC. | D40: FRETE MOT. | E40: QTD. FARDOS
A41: FINALIZADO | B41: SQA5H93 | C41: LS SIDER | E41: 157
A44: Origem: | B44: ='LIBERAÇÕES'!E46 -> SINOP-MT | C44: Coleta: | D44: ='LIBERAÇÕES'!F46 -> ALG PRANTE | E44: ='LIBERAÇÕES'!L46 -> -55 | F44: PRAZO FINALIZAR DEAD LINE (DIAS RESTANTES)
A45: Destino: | B45: ='LIBERAÇÕES'!G46 -> CUBATAO-SP | C45: Terminal: | D45: ='LIBERAÇÕES'!M46 -> CONLINE | E45: Tipo de fardo:
A46: Cliente: | B46: ='LIBERAÇÕES'!C46 -> COFCO | C46: Volume: | D46: ='LIBERAÇÕES'!I46 -> 4545 | E46: ='LIBERAÇÕES'!N46 -> FARDÃO
A47: Instrução: | B47: ='LIBERAÇÕES'!J46 -> WH-S07433-B-HCMC-FEV-01 | C47: Carregado | D47: =SUM(E50:E58) -> 1264 | E47: FRETE EMP.
...

Sheet LUCAS DO RIO VERDE
A1: Origem: | B1: ='LIBERAÇÕES'!E4 -> LUCAS DO RIO VERDE-MT | C1: Coleta: | D1: ='LIBERAÇÕES'!F4 -> ALG S COTTON | E1: ='LIBERAÇÕES'!L4 -> -73 | F1: PRAZO FINALIZAR DEAD LINE (DIAS RESTANTES)
A2: Destino: | B2: ='LIBERAÇÕES'!G4 -> SANTOS-SP | C2: Terminal: | D2: ='LIBERAÇÕES'!M4 -> ALAMO | E2: Tipo de fardo:
A3: Cliente: | B3: ='LIBERAÇÕES'!C4 -> COFCO | C3: Volume: | D3: ='LIBERAÇÕES'!I4 -> 1206 | E3: ='LIBERAÇÕES'!N4 -> FARDINHO
A4: Instrução: | B4: ='LIBERAÇÕES'!J4 -> S07453-MÃE-JAN-01 | C4: Carregado | D4: =SUM(E7:E13) -> 1206 | E4: FRETE EMP.
A5: Dead Line: | B5: ='LIBERAÇÕES'!K4 -> 46069 | C5: Saldo | D5: =D3-D4 -> 0 | E5: ='LIBERAÇÕES'!H4 -> 670
A6: STATUS | B6: PLACA | C6: TIPO VEIC. | D6: FRETE MOT. | E6: QTD. FARDOS
A7: FINALIZADO | B7: HTP9G84 | C7: 4º EIXOS | D7: 600 | E7: 180
A8: FINALIZADO | B8: QBY9G98 | C8: VANDERLEIA SIDER | D8: 600 | E8: 175
A9: FINALIZADO | B9: QBY7G60 | C9: VANDERLEIA SIDER | D9: 600 | E9: 175
A10: FINALIZADO | B10: RAK6E65 | C10: VANDERLEIA SIDER | D10: 600 | E10: 175
A11: FINALIZADO | B11: QCK1I54 | C11: 4º EIXOS | D11: 630 | E11: 175
A12: FINALIZADO | B12: TEJ1F10 | C12: 4º EIXOS | D12: 600 | E12: 162
A13: FINALIZADO | B13: TXB8F06 | C13: 4º EIXOS | D13: 600 | E13: 164
A15: Origem: | B15: ='LIBERAÇÕES'!E5 -> LUCAS DO RIO VERDE-MT | C15: Coleta: | D15: ='LIBERAÇÕES'!F5 -> ALG S COTTON | E15: ='LIBERAÇÕES'!L5 -> -76 | F15: PRAZO FINALIZAR DEAD LINE (DIAS RESTANTES)
A16: Destino: | B16: ='LIBERAÇÕES'!G5 -> CUBATAO-SP | C16: Terminal: | D16: ='LIBERAÇÕES'!M5 -> ISIS | E16: Tipo de fardo:
A17: Cliente: | B17: ='LIBERAÇÕES'!C5 -> COFCO | C17: Volume: | D17: ='LIBERAÇÕES'!I5 -> 169 | E17: ='LIBERAÇÕES'!N5 -> FARDINHO
A18: Instrução: | B18: ='LIBERAÇÕES'!J5 -> RODO-M37-JAN26-13 | C18: Carregado | D18: =SUM(E21) -> 0 | E18: FRETE EMP.
A19: Dead Line: | B19: ='LIBERAÇÕES'!K5 -> 46066 | C19: Saldo | D19: =D17-D18 -> 169 | E19: ='LIBERAÇÕES'!H5 -> 670
A20: STATUS | B20: PLACA | C20: TIPO VEIC. | D20: FRETE MOT. | E20: QTD. FARDOS
A23: Origem: | B23: ='LIBERAÇÕES'!E6 -> LUCAS DO RIO VERDE-MT | C23: Coleta: | D23: ='LIBERAÇÕES'!F6 -> ALG MARAPÉ | E23: ='LIBERAÇÕES'!L6 -> -76 | F23: PRAZO FINALIZAR DEAD LINE (DIAS RESTANTES)
A24: Destino: | B24: ='LIBERAÇÕES'!G6 -> CUBATAO-SP | C24: Terminal: | D24: ='LIBERAÇÕES'!M6 -> CONLINE | E24: Tipo de fardo:
A25: Cliente: | B25: ='LIBERAÇÕES'!C6 -> COFCO | C25: Volume: | D25: ='LIBERAÇÕES'!I6 -> 0 | E25: ='LIBERAÇÕES'!N6 -> FARDÃO
A26: Instrução: | B26: ='LIBERAÇÕES'!J6 -> WH-CONLINE-NOV25-16-SLM37 | C26: Carregado | D26: =SUM(E29:E30) -> 0 | E26: FRETE EMP.
A27: Dead Line: | B27: ='LIBERAÇÕES'!K6 -> 46066 | C27: Saldo | D27: =D25-D26 -> 0 | E27: ='LIBERAÇÕES'!H6 -> 670
A28: STATUS | B28: PLACA | C28: TIPO VEIC. | D28: FRETE MOT. | E28: QTD. FARDOS
A32: Origem: | B32: ='LIBERAÇÕES'!E7 -> LUCAS DO RIO VERDE-MT | C32: Coleta: | D32: ='LIBERAÇÕES'!F7 -> ALG MARAPÉ | E32: ='LIBERAÇÕES'!L7 -> -73 | F32: PRAZO FINALIZAR DEAD LINE (DIAS RESTANTES)
A33: Destino: | B33: ='LIBERAÇÕES'!G7 -> CUBATAO-SP | C33: Terminal: | D33: ='LIBERAÇÕES'!M7 -> ISIS | E33: Tipo de fardo:
A34: Cliente: | B34: ='LIBERAÇÕES'!C7 -> COFCO | C34: Volume: | D34: ='LIBERAÇÕES'!I7 -> 7667 | E34: ='LIBERAÇÕES'!N7 -> FARDÃO
A35: Instrução: | B35: ='LIBERAÇÕES'!J7 -> RODO-M36-JAN26-08 | C35: Carregado | D35: =SUM(E38:E80) -> 7667 | E35: FRETE EMP.
A36: Dead Line: | B36: ='LIBERAÇÕES'!K7 -> 46069 | C36: Saldo | D36: =D34-D35 -> 0 | E36: ='LIBERAÇÕES'!H7 -> 670
A37: STATUS | B37: PLACA | C37: TIPO VEIC. | D37: FRETE MOT. | E37: QTD. FARDOS
A38: FINALIZADO | B38: SLZ0J73 | C38: 4º EIXOS SIDER | D38: 600 | E38: 128
A39: FINALIZADO | B39: ANP2J95 | C39: LS GRANELEIRO | D39: 600 | E39: 150
A40: FINALIZADO | B40: AWP6J15 | C40: LS SIDER | D40: 600 | E40: 150
A41: FINALIZADO | B41: SQA5D03 | C41: LS SIDER | D41: 600 | E41: 150
A42: FINALIZADO | B42: ONT4277 | C42: LS GRANELEIRO | D42: 600 | E42: 180
A43: FINALIZADO | B43: BXF9813 | C43: LS SIDER | D43: 600 | E43: 170
A44: FINALIZADO | B44: RWG1D11 | C44: 4º EIXOS | D44: 600 | E44: 180
A45: FINALIZADO | B45: SMA7D14 | C45: 4º EIXOS | D45: 600 | E45: 180
A46: FINALIZADO | B46: NDJ3566 | C46: LS SIDER | D46: 600 | E46: 170
...

Sheet SAPEZAL
A1: Origem: | B1: ='LIBERAÇÕES'!E9 -> SAPEZAL-MT | C1: Coleta: | D1: ='LIBERAÇÕES'!F9 -> ALG RAFAELA | E1: ='LIBERAÇÕES'!L9 -> -73 | F1: PRAZO FINALIZAR DEAD LINE (DIAS RESTANTES)
A2: Destino: | B2: ='LIBERAÇÕES'!G9 -> RONDONOPOLIS-MT | C2: Terminal: | D2: ='LIBERAÇÕES'!M9 -> BRADO | E2: Tipo de fardo:
A3: Cliente: | B3: ='LIBERAÇÕES'!C9 -> SCHEFFER | C3: Volume: | D3: ='LIBERAÇÕES'!I9 -> 110 | E3: ='LIBERAÇÕES'!N9 -> FARDÃO
A4: Instrução: | B4: ='LIBERAÇÕES'!J9 -> S/BR/49 | C4: Carregado | D4: =SUM(E7) -> 110 | E4: FRETE EMP.
A5: Dead Line: | B5: ='LIBERAÇÕES'!K9 -> 46069 | C5: Saldo | D5: =D3-D4 -> 0 | E5: ='LIBERAÇÕES'!H9 -> 270
A6: STATUS | B6: PLACA | C6: TIPO VEIC. | D6: FRETE MOT. | E6: QTD. FARDOS
A7: FINALIZADO | B7: IZL7I77 | C7: LS GRANELEIRO | D7: 255 | E7: 110
A9: Origem: | B9: ='LIBERAÇÕES'!E10 -> SAPEZAL-MT | C9: Coleta: | D9: ='LIBERAÇÕES'!F10 -> ALG TRES LAGOAS | E9: ='LIBERAÇÕES'!L10 -> -73 | F9: PRAZO FINALIZAR DEAD LINE (DIAS RESTANTES)
A10: Destino: | B10: ='LIBERAÇÕES'!G10 -> RONDONOPOLIS-MT | C10: Terminal: | D10: ='LIBERAÇÕES'!M10 -> BRADO | E10: Tipo de fardo:
A11: Cliente: | B11: ='LIBERAÇÕES'!C10 -> SCHEFFER | C11: Volume: | D11: ='LIBERAÇÕES'!I10 -> 440 | E11: ='LIBERAÇÕES'!N10 -> FARDÃO
A12: Instrução: | B12: ='LIBERAÇÕES'!J10 -> S/BR/49 | C12: Carregado | D12: =SUM(E15:E16) -> 440 | E12: FRETE EMP.
A13: Dead Line: | B13: ='LIBERAÇÕES'!K10 -> 46069 | C13: Saldo | D13: =D11-D12 -> 0 | E13: ='LIBERAÇÕES'!H10 -> 270
A14: STATUS | B14: PLACA | C14: TIPO VEIC. | D14: FRETE MOT. | E14: QTD. FARDOS
A15: FINALIZADO | B15: SLH9C34 | C15: RODOTREM | D15: 240 | E15: 220
A16: FINALIZADO | B16: RAR6H56 | C16: RODOTREM | D16: 250 | E16: 220
A18: Origem: | B18: ='LIBERAÇÕES'!E30 -> SAPEZAL-MT | C18: Coleta: | D18: ='LIBERAÇÕES'!F30 -> ALG BC COTTON | E18: ='LIBERAÇÕES'!L30 -> -61 | F18: PRAZO FINALIZAR DEAD LINE (DIAS RESTANTES)
A19: Destino: | B19: ='LIBERAÇÕES'!G30 -> SANTOS-SP | C19: Terminal: | D19: ='LIBERAÇÕES'!M30 | E19: Tipo de fardo:
A20: Cliente: | B20: ='LIBERAÇÕES'!C30 -> COFCO | C20: Volume: | D20: 863 | E20: ='LIBERAÇÕES'!N30 -> FARDINHO
A21: Instrução: | B21: ='LIBERAÇÕES'!J30 -> RODO-M37-JAN26-06-B | C21: Carregado | D21: =SUM(E24:E29) -> 863 | E21: FRETE EMP.
A22: Dead Line: | B22: ='LIBERAÇÕES'!K30 -> 46081 | C22: Saldo | D22: =D20-D21 -> 0 | E22: ='LIBERAÇÕES'!H30 -> 727
A23: STATUS | B23: PLACA | C23: TIPO VEIC. | D23: FRETE MOT. | E23: QTD. FARDOS
A24: FINALIZADO | B24: TKY8G00 | C24: LS SIDER | D24: 600 | E24: 127
A25: FINALIZADO | B25: FVY8A77 | C25: LS SIDER | D25: 610 | E25: 127
A26: FINALIZADO | B26: MMK4J40 | C26: 4º EIXOS | D26: 600 | E26: 164
A27: FINALIZADO | B27: QWM8G45 | C27: 4º EIXOS | D27: 610 | E27: 170
A28: FINALIZADO | B28: QIM0I99 | C28: LS SIDER | D28: 620 | E28: 150
A29: FINALIZADO | B29: OQV7E14 | C29: LS SIDER | D29: 620 | E29: 125 | X29: 610
A31: Origem: | B31: ='LIBERAÇÕES'!E31 -> SAPEZAL-MT | C31: Coleta: | D31: ='LIBERAÇÕES'!F31 -> ALG RAFAELA | E31: ='LIBERAÇÕES'!L31 -> -58 | F31: PRAZO FINALIZAR DEAD LINE (DIAS RESTANTES)
A32: Destino: | B32: ='LIBERAÇÕES'!G31 -> SANTOS-SP | C32: Terminal: | D32: ='LIBERAÇÕES'!M31 -> SMAGALHÃES | E32: Tipo de fardo:
A33: Cliente: | B33: ='LIBERAÇÕES'!C31 -> LDC | C33: Volume: | D33: ='LIBERAÇÕES'!I31 -> 220 | E33: ='LIBERAÇÕES'!N31 -> FARDÃO
A34: Instrução: | B34: ='LIBERAÇÕES'!J31 -> RDN-EXP-SMGS-25-T531 | C34: Carregado | D34: =SUM(E37) -> 220 | E34: FRETE EMP.
A35: Dead Line: | B35: ='LIBERAÇÕES'!K31 -> 46084 | C35: Saldo | D35: =D33-D34 -> 0 | E35: ='LIBERAÇÕES'!H31 -> 660
A36: STATUS | B36: PLACA | C36: TIPO VEIC. | D36: FRETE MOT. | E36: QTD. FARDOS
A37: FINALIZADO | B37: QVV5I90 | C37: RODOTREM | D37: 630 | E37: 220
A39: Origem: | B39: ='LIBERAÇÕES'!E32 -> SAPEZAL-MT | C39: Coleta: | D39: ='LIBERAÇÕES'!F32 -> ALG RAFAELA | E39: ='LIBERAÇÕES'!L32 -> -58 | F39: PRAZO FINALIZAR DEAD LINE (DIAS RESTANTES)
A40: Destino: | B40: ='LIBERAÇÕES'!G32 -> SANTOS-SP | C40: Terminal: | D40: ='LIBERAÇÕES'!M32 -> SMAGALHÃES | E40: Tipo de fardo:
A41: Cliente: | B41: ='LIBERAÇÕES'!C32 -> LDC | C41: Volume: | D41: ='LIBERAÇÕES'!I32 -> 880 | E41: ='LIBERAÇÕES'!N32 -> FARDÃO
A42: Instrução: | B42: ='LIBERAÇÕES'!J32 -> RDN-EXP-SMGS-25-T517 | C42: Carregado | D42: =SUM(E45:E49) -> 880 | E42: FRETE EMP.
A43: Dead Line: | B43: ='LIBERAÇÕES'!K32 -> 46084 | C43: Saldo | D43: =D41-D42 -> 0 | E43: ='LIBERAÇÕES'!H32 -> 660
A44: STATUS | B44: PLACA | C44: TIPO VEIC. | D44: FRETE MOT. | E44: QTD. FARDOS
...

Sheet RONDONOPOLIS
A1: Origem: | B1: ='LIBERAÇÕES'!E25 -> RONDONOPOLIS-MT | C1: Coleta: | D1: ='LIBERAÇÕES'!F25 -> ALG TBM LOG | E1: ='LIBERAÇÕES'!L20 -> -69 | F1: PRAZO FINALIZAR DEAD LINE (DIAS RESTANTES)
A2: Destino: | B2: ='LIBERAÇÕES'!G25 -> HORIZONTE-CE | C2: Terminal: | D2: ='LIBERAÇÕES'!M25 -> SANTANA | E2: Tipo de fardo:
A3: Cliente: | B3: ='LIBERAÇÕES'!C25 -> COFCO | C3: Volume: | D3: ='LIBERAÇÕES'!I25 -> 128 | E3: ='LIBERAÇÕES'!N25 -> FARDÃO
A4: Instrução: | B4: ='LIBERAÇÕES'!J25 -> WH_STN_CONSIG-FEV-01-SANTANA | C4: Carregado | D4: =SUM(E7:E11) -> 128 | E4: FRETE EMP.
A5: Dead Line: | B5: ='LIBERAÇÕES'!K25 -> 46071 | C5: Saldo | D5: =D3-D4 -> 0 | E5: ='LIBERAÇÕES'!H25 -> 990
A6: STATUS | B6: PLACA | C6: TIPO VEIC. | D6: FRETE MOT. | E6: QTD. FARDOS
A7: FINALIZADO | B7: HFD3584 | C7: LS SIDER | D7: R$ 770,00 | E7: 128
A13: Origem: | B13: ='LIBERAÇÕES'!E26 -> RONDONOPOLIS-MT | C13: Coleta: | D13: ='LIBERAÇÕES'!F26 -> ALG TBM LOG | E13: ='LIBERAÇÕES'!L26 -> -71 | F13: PRAZO FINALIZAR DEAD LINE (DIAS RESTANTES)
A14: Destino: | B14: ='LIBERAÇÕES'!G26 -> SANTOS-SP | C14: Terminal: | D14: ='LIBERAÇÕES'!M26 -> CONLINE | E14: Tipo de fardo:
A15: Cliente: | B15: ='LIBERAÇÕES'!C26 -> COFCO | C15: Volume: | D15: ='LIBERAÇÕES'!I26 -> 0 | E15: ='LIBERAÇÕES'!N26 -> FARDÃO
A16: Instrução: | B16: ='LIBERAÇÕES'!J26 -> WH-S07405-JAN-01 | C16: Carregado | D16: =SUM(E19:E28) -> 0 | E16: FRETE EMP.
A17: Dead Line: | B17: ='LIBERAÇÕES'!K26 -> 46071 | C17: Saldo | D17: =D15-D16 -> 0 | E17: ='LIBERAÇÕES'!H26 -> 585
A18: STATUS | B18: PLACA | C18: TIPO VEIC. | D18: FRETE MOT. | E18: QTD. FARDOS
A30: Origem: | B30: ='LIBERAÇÕES'!E27 -> RONDONOPOLIS-MT | C30: Coleta: | D30: ='LIBERAÇÕES'!F27 -> ALG TBM LOG | E30: ='LIBERAÇÕES'!L27 -> -71 | F30: PRAZO FINALIZAR DEAD LINE (DIAS RESTANTES)
A31: Destino: | B31: ='LIBERAÇÕES'!G27 -> GUARUJA-SP | C31: Terminal: | D31: ='LIBERAÇÕES'!M27 -> CORTES | E31: Tipo de fardo:
A32: Cliente: | B32: ='LIBERAÇÕES'!C27 -> COFCO | C32: Volume: | D32: ='LIBERAÇÕES'!I27 -> 0 | E32: ='LIBERAÇÕES'!N27 -> FARDÃO
A33: Instrução: | B33: ='LIBERAÇÕES'!J27 -> S07389-JAN-01 | C33: Carregado | D33: =SUM(E36:E45) -> 0 | E33: FRETE EMP.
A34: Dead Line: | B34: ='LIBERAÇÕES'!K27 -> 46071 | C34: Saldo | D34: =D32-D33 -> 0 | E34: ='LIBERAÇÕES'!H27 -> 585
A35: STATUS | B35: PLACA | C35: TIPO VEIC. | D35: FRETE MOT. | E35: QTD. FARDOS
A47: Origem: | B47: ='LIBERAÇÕES'!E28 -> RONDONOPOLIS-MT | C47: Coleta: | D47: ='LIBERAÇÕES'!F26 -> ALG TBM LOG | E47: ='LIBERAÇÕES'!L28 -> -71 | F47: PRAZO FINALIZAR DEAD LINE (DIAS RESTANTES)
A48: Destino: | B48: ='LIBERAÇÕES'!G28 -> CUBATAO-SP | C48: Terminal: | D48: ='LIBERAÇÕES'!M28 -> ISIS | E48: Tipo de fardo:
A49: Cliente: | B49: ='LIBERAÇÕES'!C28 -> COFCO | C49: Volume: | D49: ='LIBERAÇÕES'!I28 -> 2168 | E49: ='LIBERAÇÕES'!N28 -> FARDÃO
A50: Instrução: | B50: ='LIBERAÇÕES'!J28 -> S07475-MÃE-FEV-02 | C50: Carregado | D50: =SUM(E53:E72) -> 2168 | E50: FRETE EMP.
A51: Dead Line: | B51: ='LIBERAÇÕES'!K28 -> 46071 | C51: Saldo | D51: =D49-D50 -> 0 | E51: ='LIBERAÇÕES'!H28 -> 585
A52: STATUS | B52: PLACA | C52: TIPO VEIC. | D52: FRETE MOT. | E52: QTD. FARDOS
A53: FINALIZADO | B53: GAA9F11 | C53: LS SIDER | D53: R$ 450,00 | E53: 165
A54: FINALIZADO | B54: JBU8F32 | C54: 4º EIXOS | D54: R$ 450,00 | E54: 159
A55: FINALIZADO | B55: JCU8D98 | C55: 4º EIXOS | D55: R$ 450,00 | E55: 170
A56: FINALIZADO | B56: TIZ4E37 | C56: 4º EIXOS SIDER | D56: R$ 450,00 | E56: 157
A57: AGENDADO | B57: AJS6E33 | C57: LS SIDER | D57: R$ 450,00 | E57: 145
A58: FINALIZADO | B58: EQD9H33 | C58: LS SIDER | D58: R$ 450,00 | E58: 130
A59: AGENDADO | B59: TLT5E83 | C59: 4º EIXOS SIDER | D59: R$ 450,00 | E59: 156
A60: FINALIZADO | B60: BBN8H87 | C60: TRUCK | D60: R$ 425,00 | E60: 135
A61: AGENDADO | B61: EII8J02 | C61: BITREM | D61: R$ 450,00 | E61: 177
A63: FALTA AGENDAR | B63: ASQ5C51 | C63: LS GRANELEIRO | D63: R$ 450,00 | E63: 160
A64: AGENDADO | B64: GEU7B58 | C64: LS SIDER | D64: R$ 450,00 | E64: 139
A65: AGENDADO | B65: SZR2H65 | C65: LS SIDER | D65: R$ 450,00 | E65: 176
... A67: FALTA AGENDAR | B67: AWZ0I48 | C67: LS SIDER | D67: R$ 450,00 | E67: 152
A74: Origem: | B74: ='LIBERAÇÕES'!E33 -> CAMPO VERDE-MT | C74: Coleta: | D74: ='LIBERAÇÕES'!F33 -> ALG PRINCESA | E74: ='LIBERAÇÕES'!L33 -> -55 | F74: PRAZO FINALIZAR DEAD LINE (DIAS RESTANTES)
A75: Destino: | B75: ='LIBERAÇÕES'!G33 -> SANTOS-SP | C75: Terminal: | D75: ='LIBERAÇÕES'!M33 | E75: Tipo de fardo:
...

Sheet NOVA MUTUM
A2: Origem: | B2: SAPEZAL/MT | C2: Coleta: | D2: ALG. TRES LAGOAS | E2: ='LIBERAÇÕES'!L10 -> -73
A3: Destino: | B3: RONDONÓPOLIS/MT | C3: Terminal: | D3: BRADO | E3: Tipo de fardo:
A4: Cliente: | B4: SCHEFFER | C4: Volume: | D4: 202 | E4: FARDÃO
A5: Instrução: | B5: S51580.B04 | C5: Carregado | D5: =SUM(E8:E13) -> 202 | E5: FRETE EMP.
A6: Dead Line: | B6: 03/05 A 05/05 | C6: Saldo | D6: =D4-D5 -> 0 | E6: 230
A7: STATUS | B7: PLACA | C7: TIPO VEIC. | D7: FRETE MOT. | E7: QTD. FARDOS
A8: AGUARDANDO CARREGAMENTO | B8: SPT3D39 | C8: RODOTREM | D8: 200 | E8: 202

Sheet PRIMAVERA DO LESTE
A1: Origem: | B1: ='LIBERAÇÕES'!E3 -> NOVO SAO JOAQUIM-MT | C1: Coleta: | D1: ='LIBERAÇÕES'!F3 -> ALG ITAQUERE | E1: ='LIBERAÇÕES'!L3 -> -80 | F1: PRAZO FINALIZAR DEAD LINE (DIAS RESTANTES)
A2: Destino: | B2: ='LIBERAÇÕES'!G3 -> SANTOS-SP | C2: Terminal: | D2: ='LIBERAÇÕES'!M3 -> DALASTRA | E2: Tipo de fardo:
A3: Cliente: | B3: ='LIBERAÇÕES'!C3 -> BRASIL AGRO | C3: Volume: | D3: ='LIBERAÇÕES'!I3 -> 1512 | E3: ='LIBERAÇÕES'!N3 -> FARDINHO
A4: Instrução: | B4: ='LIBERAÇÕES'!J3 | C4: Carregado | D4: =SUM(E7:E15) -> 1512 | E4: FRETE EMP.
A5: Dead Line: | B5: ='LIBERAÇÕES'!K3 -> 46062 | C5: Saldo | D5: =D3-D4 -> 0 | E5: ='LIBERAÇÕES'!H3 -> 492
A6: STATUS | B6: PLACA | C6: TIPO VEIC. | D6: FRETE MOT. | E6: QTD. FARDOS
A7: FINALIZADO | B7: EVO9G44 | C7: VANDERLEIA SIDER | D7: 470 | E7: 168
A8: FINALIZADO | B8: PTW9A89 | C8: RODOTREM | D8: 470 | E8: 240
A9: FINALIZADO | B9: GHC2I03 | C9: VANDERLEIA SIDER | D9: 470 | E9: 163
A10: FINALIZADO | B10: RBU0C70 | C10: VANDERLEIA SIDER | D10: 470 | E10: 160
A11: FINALIZADO | B11: DBL4I38 | C11: 4º EIXOS | D11: 470 | E11: 156
A12: FINALIZADO | B12: AZT6C46 | C12: LS GRANELEIRO | D12: 470 | E12: 144
A13: FINALIZADO | B13: JDH0D86 | C13: RODOTREM SIDER | D13: 490 | E13: 215
A14: FINALIZADO | B14: ENR6109 | C14: LS SIDER | D14: 500 | E14: 133
A15: FINALIZADO | B15: DOG4A62 | C15: LS SIDER | D15: 500 | E15: 133
A17: Origem: | B17: ='LIBERAÇÕES'!E24 -> PRIMAVERA DO LESTE-MT | C17: Coleta: | D17: ='LIBERAÇÕES'!F24 -> ALG NOVA GERAÇÃO | E17: ='LIBERAÇÕES'!L24 -> -69 | F17: PRAZO FINALIZAR DEAD LINE (DIAS RESTANTES)
A18: Destino: | B18: ='LIBERAÇÕES'!G24 -> CUBATAO-SP | C18: Terminal: | D18: ='LIBERAÇÕES'!M24 -> ISIS | E18: Tipo de fardo:
A19: Cliente: | B19: ='LIBERAÇÕES'!C24 -> COFCO | C19: Volume: | D19: ='LIBERAÇÕES'!I24 -> 1865 | E19: ='LIBERAÇÕES'!N24 -> FARDINHO
A20: Instrução: | B20: ='LIBERAÇÕES'!J24 -> RODO-M37-JAN26-11 | C20: Carregado | D20: =SUM(E23:E34) -> 1865 | E20: FRETE EMP.
A21: Dead Line: | B21: ='LIBERAÇÕES'!K24 -> 46073 | C21: Saldo | D21: =D19-D20 -> 0 | E21: ='LIBERAÇÕES'!H24 -> 530
A22: STATUS | B22: PLACA | C22: TIPO VEIC. | D22: FRETE MOT. | E22: QTD. FARDOS
A23: FINALIZADO | B23: GJX1A53 | C23: LS SIDER | D23: 480 | E23: 176
A24: FINALIZADO | B24: RNG4D20 | C24: LS SIDER | D24: 480 | E24: 158
A25: FINALIZADO | B25: JCN2B85 | C25: LS GRANELEIRO | D25: 480 | E25: 139
A26: FINALIZADO | B26: EJW1540 | C26: LS SIDER | D26: 480 | E26: 152
A27: FINALIZADO | B27: TFP8G43 | C27: 4º EIXOS | D27: 480 | E27: 163
A28: FINALIZADO | B28: MCU0I78 | C28: LS GRANELEIRO | D28: 480 | E28: 160
A29: FINALIZADO | B29: SPT3D39 | C29: RODOTREM | D29: FROTA | E29: 240
A30: FINALIZADO | B30: EPA6D40 | C30: 4º EIXOS SIDER | D30: 480 | E30: 156
A31: FINALIZADO | B31: RAY8C53 | C31: RODOTREM | D31: FROTA | E31: 214
A32: FINALIZADO | B32: MLT3I14 | C32: VANDERLEIA | D32: 480 | E32: 166
A33: FINALIZADO | B33: AXY6A37 | C33: LS SIDER | D33: 480 | E33: 141
B34: LOTE FINALIZADO
A36: Origem: | B36: ='LIBERAÇÕES'!E29 -> NOVO SAO JOAQUIM-MT | C36: Coleta: | D36: ='LIBERAÇÕES'!F29 -> ALG ITAQUERE | E36: ='LIBERAÇÕES'!L29 -> -65 | F36: PRAZO FINALIZAR DEAD LINE (DIAS RESTANTES)
A37: Destino: | B37: ='LIBERAÇÕES'!G29 -> GUARUJA-SP | C37: Terminal: | D37: ='LIBERAÇÕES'!M29 -> CORTES | E37: Tipo de fardo: | F37: BOOKING 266362944
A38: Cliente: | B38: ='LIBERAÇÕES'!C29 -> BRASIL AGRO | C38: Volume: | D38: ='LIBERAÇÕES'!I29 -> 718 | E38: ='LIBERAÇÕES'!N29 -> FARDINHO
A39: Instrução: | B39: ='LIBERAÇÕES'!J29 -> AF237/2025 | C39: Carregado | D39: =SUM(E42:E46) -> 718 | E39: FRETE EMP.
A40: Dead Line: | B40: ='LIBERAÇÕES'!K29 -> 46077 | C40: Saldo | D40: =D38-D39 -> 0 | E40: ='LIBERAÇÕES'!H29 -> 570
A41: STATUS | B41: PLACA | C41: TIPO VEIC. | D41: FRETE MOT. | E41: QTD. FARDOS
A42: FINALIZADO | B42: IZL7I77 | C42: LS SIDER | D42: 530 | E42: 144
...

Sheet SORRISO
A1: Origem: | B1: ='LIBERAÇÕES'!E20 -> SORRISO-MT | C1: Coleta: | D1: ='LIBERAÇÕES'!F20 -> ALG COTTON ESPERANÇA | E1: ='LIBERAÇÕES'!L20 -> -69 | F1: PRAZO FINALIZAR DEAD LINE (DIAS RESTANTES)
A2: Destino: | B2: ='LIBERAÇÕES'!G20 -> NATAL-RN | C2: Terminal: | D2: ='LIBERAÇÕES'!M20 -> VICUNHA | E2: Tipo de fardo:
A3: Cliente: | B3: ='LIBERAÇÕES'!C20 -> NUTRADE | C3: Volume: | D3: ='LIBERAÇÕES'!I20 -> 686 | E3: ='LIBERAÇÕES'!N20 -> FARDINHO
A4: Instrução: | B4: ='LIBERAÇÕES'!J20 -> 250071-04 | C4: Carregado | D4: =SUM(E7:E11) -> 686 | E4: FRETE EMP.
A5: Dead Line: | B5: ='LIBERAÇÕES'!K20 -> 46073 | C5: Saldo | D5: =D3-D4 -> 0 | E5: ='LIBERAÇÕES'!H20 -> 862
A6: STATUS | B6: PLACA | C6: TIPO VEIC. | D6: FRETE MOT. | E6: QTD. FARDOS
A7: FINALIZADO | B7: JAW7D74 | C7: RODOTREM | D7: 785 | E7: 230
A8: FINALIZADO | B8: JBN0D17 | C8: RODOTREM | D8: 760 | E8: 228
A9: FINALIZADO | B9: JBW1A82 | C9: RODOTREM | D9: 760 | E9: 228
A13: Origem: | B13: ='LIBERAÇÕES'!D61 -> SORRISO-MT | C13: Coleta: | D13: ='LIBERAÇÕES'!F61 -> ALG CELESTE | E13: ='LIBERAÇÕES'!L32 -> -58 | F13: PRAZO FINALIZAR DEAD LINE (DIAS RESTANTES)
A14: Destino: | B14: ='LIBERAÇÕES'!G61 -> RONDONOPOLIS-MT | C14: Terminal: | D14: ='LIBERAÇÕES'!M61 -> EISA | E14: Tipo de fardo:
A15: Cliente: | B15: ='LIBERAÇÕES'!C61 -> NUTRADE | C15: Volume: | D15: ='LIBERAÇÕES'!I61 -> 298
A16: Instrução: | B16: ='LIBERAÇÕES'!J61 -> SIRON-EXP-3155257015-055-01A | C16: Carregado | D16: =E19+E20+E21+E22 -> 298 | E16: FRETE EMP.
A17: Dead Line: | B17: ='LIBERAÇÕES'!K61 -> 46112 | C17: Saldo | D17: =D15-D16 -> 0
A18: STATUS | B18: PLACA | C18: TIPO VEIC. | D18: FRETE MOT. | E18: QTD. FARDOS
A19: AGUARDANDO NFE | B19: MIX0A83 | C19: LS GRANELEIRO | D19: 210 | E19: 135
A20: CONTRATADO | B20: RAF5B36 | C20: 4º EIXOS SIDER | D20: 215 | E20: 163

Sheet CAMPO NOVO 
A1: ORIEGEM: | B1: ='LIBERAÇÕES'!E60 -> CAMPO NOVO DO PARECIS-MT | C1: Coleta: | D1: ='LIBERAÇÕES'!F60 -> ALG COTTON CAMPO | F1: PRAZO FINALIZAR DEAD LINE (DIAS RESTANTES)
A2: Destino: | B2: ='LIBERAÇÕES'!G60 -> CUBATAO-SP | C2: Terminal: | D2: ='LIBERAÇÕES'!M60 -> LDC | E2: Tipo de fardo:
A3: Cliente: | B3: ='LIBERAÇÕES'!C60 -> NUTRADE | C3: Volume: | D3: ='LIBERAÇÕES'!I60 -> 520 | E3: ='LIBERAÇÕES'!N25 -> FARDÃO
A4: Instrução: | B4: ='LIBERAÇÕES'!J60 -> SI RDN-EXP-CBT-25-AL158 | C4: Carregado | D4: =E7+E8+E9+E10+E11 -> 520 | E4: FRETE EMP.
A5: Dead Line: | B5: ='LIBERAÇÕES'!K60 -> 46112 | C5: Saldo | D5: =D3-D4 -> 0 | E5: 640
A6: STATUS | B6: PLACA | C6: TIPO VEIC. | D6: FRETE MOT. | E6: QTD. FARDOS
A7: LIBERADO | B7: RVD4J01 | C7: RODOTREM | D7: 600 | E7: 206
A8: LIBERADO | B8: RRZ1F69 | C8: RODOTREM | D8: 600 | E8: 206
A9: LIBERADO | B9: IOQ7I56 | C9: LS GRANELEIRO | D9: 600 | E9: 108
A13: Origem: | B13: ='LIBERAÇÕES'!E65 -> DIAMANTINO-MT | C13: Coleta: | D13: ='LIBERAÇÕES'!F65 -> ALG FALAVINHA | F13: PRAZO FINALIZAR DEAD LINE (DIAS RESTANTES)
A14: Destino: | B14: ='LIBERAÇÕES'!G65 -> RONDONOPOLIS-MT | C14: Terminal: | D14: ='LIBERAÇÕES'!M64 -> EISA | E14: Tipo de fardo:
A15: Cliente: | B15: ='LIBERAÇÕES'!C65 -> NUTRADE | C15: Volume: | D15: ='LIBERAÇÕES'!I65 -> 130 | E15: ='LIBERAÇÕES'!N37 -> FARDÃO
A16: Instrução: | B16: ='LIBERAÇÕES'!J65 -> SIRON-EXP-3155257015-055-02A | C16: Carregado | D16: =E19 -> 130 | E16: FRETE EMP.
A17: Dead Line: | B17: ='LIBERAÇÕES'!K65 -> 46112 | C17: Saldo | D17: =D15-D16 -> 0 | E17: ='LIBERAÇÕES'!H65 -> 255
A18: STATUS | B18: PLACA | C18: TIPO VEIC. | D18: FRETE MOT. | E18: QTD. FARDOS
A19: LIBERADO | B19: FQO8E13 | C19: 4º EIXOS | D19: 210 | E19: 130
A21: Origem: | B21: ='LIBERAÇÕES'!E69 -> NOVA MARINGA-MT | C21: Coleta: | D21: ='LIBERAÇÕES'!F69 -> ALG GFO COTTON | F21: PRAZO FINALIZAR DEAD LINE (DIAS RESTANTES)
A22: Destino: | B22: ='LIBERAÇÕES'!G69 -> RONDONOPOLIS-MT | C22: Terminal: | D22: ='LIBERAÇÕES'!M69 -> TBM LOG | E22: Tipo de fardo:
A23: Cliente: | B23: ='LIBERAÇÕES'!C69 -> COFCO | C23: Volume: | D23: ='LIBERAÇÕES'!I69 -> 1272 | E23: ='LIBERAÇÕES'!N45 -> FARDINHO
A24: Instrução: | B24: ='LIBERAÇÕES'!J69 -> WH-TBM-MAR26-03 | C24: Carregado | D24: =E27+E28+E29+E30+E31+E32+E33+E34+E35 -> 1272 | E24: FRETE EMP.
A25: Dead Line: | B25: ='LIBERAÇÕES'!K85 -> 46130 | C25: Saldo | D25: 0 | E25: ='LIBERAÇÕES'!H69 -> 350
A26: STATUS | B26: PLACA | C26: TIPO VEIC. | D26: FRETE MOT. | E26: QTD. FARDOS
A27: LIBERADO | B27: RDX9B55 | C27: 4º EIXOS | D27: 280 | E27: 148
A28: LIBERADO | B28: RDU2J76 | C28: 4º EIXOS | D28: 280 | E28: 148
A29: LIBERADO | B29: MJC5524 | C29: 4º EIXOS | D29: 280 | E29: 148
A30: LIBERADO | B30: MWW8G26 | C30: LS SIDER | D30: 280 | E30: 130
A31: LIBERADO | B31: JBE9E42 | C31: LS SIDER | D31: 280 | E31: 128
A32: LIBERADO | B32: JAC7J26 | C32: RODOTREM | D32: 280 | E32: 204
A33: LIBERADO | B33: BCN3G07 | C33: BITREM | D33: 280 | E33: 160
A34: EM TRANSITO | B34: QAH2F99 | C34: RODOTREM | D34: 280 | E34: 206
